2024-01-18 20:34:41,925 INFO    StreamThr :172158 [internal.py:wandb_internal():86] W&B internal server running at pid: 172158, started at: 2024-01-18 20:34:41.923198
2024-01-18 20:34:41,931 DEBUG   HandlerThread:172158 [handler.py:handle_request():146] handle_request: status
2024-01-18 20:34:41,958 INFO    WriterThread:172158 [datastore.py:open_for_write():87] open: ./wandb/run-20240118_203441-9t6pak46/run-9t6pak46.wandb
2024-01-18 20:34:41,960 DEBUG   SenderThread:172158 [sender.py:send():382] send: header
2024-01-18 20:34:41,975 DEBUG   SenderThread:172158 [sender.py:send():382] send: run
2024-01-18 20:34:41,982 INFO    SenderThread:172158 [sender.py:_maybe_setup_resume():763] checking resume status for raviraja/MLOps Basics/9t6pak46
2024-01-18 20:34:46,083 ERROR   SenderThread:172158 [internal_api.py:execute():373] 404 response executing GraphQL.
2024-01-18 20:34:46,083 ERROR   SenderThread:172158 [internal_api.py:execute():374] {"errors":[{"message":"project not found","path":["upsertBucket"]}],"data":{"upsertBucket":null}}
2024-01-18 20:34:46,084 ERROR   SenderThread:172158 [sender.py:send_run():987] It appears that you do not have permission to access the requested resource. Please reach out to the project owner to grant you access. If you have the correct permissions, verify that there are no issues with your networking setup.(Error 404: Not Found)
Traceback (most recent call last):
  File "/home/jithish/.cache/pypoetry/virtualenvs/mlops-project-0-LIiUPOOO-py3.11/lib/python3.11/site-packages/wandb/sdk/lib/retry.py", line 131, in __call__
    result = self._call_fn(*args, **kwargs)
             ^^^^^^^^^^^^^^^^^^^^^^^^^^^^^^
  File "/home/jithish/.cache/pypoetry/virtualenvs/mlops-project-0-LIiUPOOO-py3.11/lib/python3.11/site-packages/wandb/sdk/internal/internal_api.py", line 369, in execute
    return self.client.execute(*args, **kwargs)  # type: ignore
           ^^^^^^^^^^^^^^^^^^^^^^^^^^^^^^^^^^^^
  File "/home/jithish/.cache/pypoetry/virtualenvs/mlops-project-0-LIiUPOOO-py3.11/lib/python3.11/site-packages/wandb/vendor/gql-0.2.0/wandb_gql/client.py", line 52, in execute
    result = self._get_result(document, *args, **kwargs)
             ^^^^^^^^^^^^^^^^^^^^^^^^^^^^^^^^^^^^^^^^^^^
  File "/home/jithish/.cache/pypoetry/virtualenvs/mlops-project-0-LIiUPOOO-py3.11/lib/python3.11/site-packages/wandb/vendor/gql-0.2.0/wandb_gql/client.py", line 60, in _get_result
    return self.transport.execute(document, *args, **kwargs)
           ^^^^^^^^^^^^^^^^^^^^^^^^^^^^^^^^^^^^^^^^^^^^^^^^^
  File "/home/jithish/.cache/pypoetry/virtualenvs/mlops-project-0-LIiUPOOO-py3.11/lib/python3.11/site-packages/wandb/sdk/lib/gql_request.py", line 59, in execute
    request.raise_for_status()
  File "/home/jithish/.cache/pypoetry/virtualenvs/mlops-project-0-LIiUPOOO-py3.11/lib/python3.11/site-packages/requests/models.py", line 1021, in raise_for_status
    raise HTTPError(http_error_msg, response=self)
requests.exceptions.HTTPError: 404 Client Error: Not Found for url: https://api.wandb.ai/graphql

During handling of the above exception, another exception occurred:

Traceback (most recent call last):
  File "/home/jithish/.cache/pypoetry/virtualenvs/mlops-project-0-LIiUPOOO-py3.11/lib/python3.11/site-packages/wandb/sdk/internal/sender.py", line 985, in send_run
    self._init_run(run, config_value_dict)
  File "/home/jithish/.cache/pypoetry/virtualenvs/mlops-project-0-LIiUPOOO-py3.11/lib/python3.11/site-packages/wandb/sdk/internal/sender.py", line 1027, in _init_run
    server_run, inserted, server_messages = self._api.upsert_run(
                                            ^^^^^^^^^^^^^^^^^^^^^
  File "/home/jithish/.cache/pypoetry/virtualenvs/mlops-project-0-LIiUPOOO-py3.11/lib/python3.11/site-packages/wandb/apis/normalize.py", line 73, in wrapper
    raise err
  File "/home/jithish/.cache/pypoetry/virtualenvs/mlops-project-0-LIiUPOOO-py3.11/lib/python3.11/site-packages/wandb/apis/normalize.py", line 41, in wrapper
    return func(*args, **kwargs)
           ^^^^^^^^^^^^^^^^^^^^^
  File "/home/jithish/.cache/pypoetry/virtualenvs/mlops-project-0-LIiUPOOO-py3.11/lib/python3.11/site-packages/wandb/sdk/internal/internal_api.py", line 2216, in upsert_run
    response = self.gql(
               ^^^^^^^^^
  File "/home/jithish/.cache/pypoetry/virtualenvs/mlops-project-0-LIiUPOOO-py3.11/lib/python3.11/site-packages/wandb/sdk/internal/internal_api.py", line 341, in gql
    ret = self._retry_gql(
          ^^^^^^^^^^^^^^^^
  File "/home/jithish/.cache/pypoetry/virtualenvs/mlops-project-0-LIiUPOOO-py3.11/lib/python3.11/site-packages/wandb/sdk/lib/retry.py", line 147, in __call__
    retry_timedelta_triggered = check_retry_fn(e)
                                ^^^^^^^^^^^^^^^^^
  File "/home/jithish/.cache/pypoetry/virtualenvs/mlops-project-0-LIiUPOOO-py3.11/lib/python3.11/site-packages/wandb/util.py", line 965, in check_retry_fn
    return fallback_retry_fn(e)
           ^^^^^^^^^^^^^^^^^^^^
  File "/home/jithish/.cache/pypoetry/virtualenvs/mlops-project-0-LIiUPOOO-py3.11/lib/python3.11/site-packages/wandb/util.py", line 907, in no_retry_auth
    raise CommError(
wandb.errors.CommError: It appears that you do not have permission to access the requested resource. Please reach out to the project owner to grant you access. If you have the correct permissions, verify that there are no issues with your networking setup.(Error 404: Not Found)
2024-01-18 20:34:46,639 DEBUG   HandlerThread:172158 [handler.py:handle_request():146] handle_request: shutdown
2024-01-18 20:34:46,640 INFO    HandlerThread:172158 [handler.py:finish():869] shutting down handler
2024-01-18 20:34:46,976 INFO    WriterThread:172158 [datastore.py:close():296] close: ./wandb/run-20240118_203441-9t6pak46/run-9t6pak46.wandb
2024-01-18 20:34:47,095 INFO    SenderThread:172158 [sender.py:finish():1572] shutting down sender
