2024-01-19 19:00:40,497 INFO    StreamThr :17886 [internal.py:wandb_internal():86] W&B internal server running at pid: 17886, started at: 2024-01-19 19:00:40.496230
2024-01-19 19:00:40,502 DEBUG   HandlerThread:17886 [handler.py:handle_request():146] handle_request: status
2024-01-19 19:00:40,513 INFO    WriterThread:17886 [datastore.py:open_for_write():87] open: /home/jithish/Documents/mlops_project_0/week_2/outputs/2024-01-19/19-00-27/wandb/run-20240119_190040-q5hq08un/run-q5hq08un.wandb
2024-01-19 19:00:40,513 DEBUG   SenderThread:17886 [sender.py:send():382] send: header
2024-01-19 19:00:40,518 DEBUG   SenderThread:17886 [sender.py:send():382] send: run
2024-01-19 19:00:40,520 INFO    SenderThread:17886 [sender.py:_maybe_setup_resume():763] checking resume status for raviraja/MLOps Basics/q5hq08un
2024-01-19 19:00:41,318 ERROR   SenderThread:17886 [internal_api.py:execute():373] 404 response executing GraphQL.
2024-01-19 19:00:41,318 ERROR   SenderThread:17886 [internal_api.py:execute():374] {"errors":[{"message":"project not found","path":["upsertBucket"]}],"data":{"upsertBucket":null}}
2024-01-19 19:00:41,318 ERROR   SenderThread:17886 [sender.py:send_run():987] It appears that you do not have permission to access the requested resource. Please reach out to the project owner to grant you access. If you have the correct permissions, verify that there are no issues with your networking setup.(Error 404: Not Found)
Traceback (most recent call last):
  File "/home/jithish/.cache/pypoetry/virtualenvs/mlops-project-0-LIiUPOOO-py3.11/lib/python3.11/site-packages/wandb/sdk/lib/retry.py", line 131, in __call__
    result = self._call_fn(*args, **kwargs)
             ^^^^^^^^^^^^^^^^^^^^^^^^^^^^^^
  File "/home/jithish/.cache/pypoetry/virtualenvs/mlops-project-0-LIiUPOOO-py3.11/lib/python3.11/site-packages/wandb/sdk/internal/internal_api.py", line 369, in execute
    return self.client.execute(*args, **kwargs)  # type: ignore
           ^^^^^^^^^^^^^^^^^^^^^^^^^^^^^^^^^^^^
  File "/home/jithish/.cache/pypoetry/virtualenvs/mlops-project-0-LIiUPOOO-py3.11/lib/python3.11/site-packages/wandb/vendor/gql-0.2.0/wandb_gql/client.py", line 52, in execute
    result = self._get_result(document, *args, **kwargs)
             ^^^^^^^^^^^^^^^^^^^^^^^^^^^^^^^^^^^^^^^^^^^
  File "/home/jithish/.cache/pypoetry/virtualenvs/mlops-project-0-LIiUPOOO-py3.11/lib/python3.11/site-packages/wandb/vendor/gql-0.2.0/wandb_gql/client.py", line 60, in _get_result
    return self.transport.execute(document, *args, **kwargs)
           ^^^^^^^^^^^^^^^^^^^^^^^^^^^^^^^^^^^^^^^^^^^^^^^^^
  File "/home/jithish/.cache/pypoetry/virtualenvs/mlops-project-0-LIiUPOOO-py3.11/lib/python3.11/site-packages/wandb/sdk/lib/gql_request.py", line 59, in execute
    request.raise_for_status()
  File "/home/jithish/.cache/pypoetry/virtualenvs/mlops-project-0-LIiUPOOO-py3.11/lib/python3.11/site-packages/requests/models.py", line 1021, in raise_for_status
    raise HTTPError(http_error_msg, response=self)
requests.exceptions.HTTPError: 404 Client Error: Not Found for url: https://api.wandb.ai/graphql

During handling of the above exception, another exception occurred:

Traceback (most recent call last):
  File "/home/jithish/.cache/pypoetry/virtualenvs/mlops-project-0-LIiUPOOO-py3.11/lib/python3.11/site-packages/wandb/sdk/internal/sender.py", line 985, in send_run
    self._init_run(run, config_value_dict)
  File "/home/jithish/.cache/pypoetry/virtualenvs/mlops-project-0-LIiUPOOO-py3.11/lib/python3.11/site-packages/wandb/sdk/internal/sender.py", line 1027, in _init_run
    server_run, inserted, server_messages = self._api.upsert_run(
                                            ^^^^^^^^^^^^^^^^^^^^^
  File "/home/jithish/.cache/pypoetry/virtualenvs/mlops-project-0-LIiUPOOO-py3.11/lib/python3.11/site-packages/wandb/apis/normalize.py", line 73, in wrapper
    raise err
  File "/home/jithish/.cache/pypoetry/virtualenvs/mlops-project-0-LIiUPOOO-py3.11/lib/python3.11/site-packages/wandb/apis/normalize.py", line 41, in wrapper
    return func(*args, **kwargs)
           ^^^^^^^^^^^^^^^^^^^^^
  File "/home/jithish/.cache/pypoetry/virtualenvs/mlops-project-0-LIiUPOOO-py3.11/lib/python3.11/site-packages/wandb/sdk/internal/internal_api.py", line 2216, in upsert_run
    response = self.gql(
               ^^^^^^^^^
  File "/home/jithish/.cache/pypoetry/virtualenvs/mlops-project-0-LIiUPOOO-py3.11/lib/python3.11/site-packages/wandb/sdk/internal/internal_api.py", line 341, in gql
    ret = self._retry_gql(
          ^^^^^^^^^^^^^^^^
  File "/home/jithish/.cache/pypoetry/virtualenvs/mlops-project-0-LIiUPOOO-py3.11/lib/python3.11/site-packages/wandb/sdk/lib/retry.py", line 147, in __call__
    retry_timedelta_triggered = check_retry_fn(e)
                                ^^^^^^^^^^^^^^^^^
  File "/home/jithish/.cache/pypoetry/virtualenvs/mlops-project-0-LIiUPOOO-py3.11/lib/python3.11/site-packages/wandb/util.py", line 965, in check_retry_fn
    return fallback_retry_fn(e)
           ^^^^^^^^^^^^^^^^^^^^
  File "/home/jithish/.cache/pypoetry/virtualenvs/mlops-project-0-LIiUPOOO-py3.11/lib/python3.11/site-packages/wandb/util.py", line 907, in no_retry_auth
    raise CommError(
wandb.errors.CommError: It appears that you do not have permission to access the requested resource. Please reach out to the project owner to grant you access. If you have the correct permissions, verify that there are no issues with your networking setup.(Error 404: Not Found)
2024-01-19 19:00:41,720 DEBUG   HandlerThread:17886 [handler.py:handle_request():146] handle_request: shutdown
2024-01-19 19:00:41,720 INFO    HandlerThread:17886 [handler.py:finish():869] shutting down handler
2024-01-19 19:00:42,333 INFO    SenderThread:17886 [sender.py:finish():1572] shutting down sender
2024-01-19 19:00:42,519 INFO    WriterThread:17886 [datastore.py:close():296] close: /home/jithish/Documents/mlops_project_0/week_2/outputs/2024-01-19/19-00-27/wandb/run-20240119_190040-q5hq08un/run-q5hq08un.wandb
